<?xml version="1.0" ?>
    <robot name="explorer">
        <link name="world"/> 

        <link name="base">
            <visual>
                <geometry>
                    <box size="0.55 0.5 0.05"/>
                </geometry> 

                <material name = "red">
                    <color rgba="1 0 0 1"/>
                </material>
            </visual>

            <inertial>
                <origin xyz="0.0 0.0 0.0" rpy="0.0 0.0 0.0"/>
                <mass value="1"/>
                <inertia ixx="0.01" ixy="0.0" ixz="0.0" iyy="0.01" iyz="0.0" izz="0.01"/>
            </inertial>

            <collision>
               <geometry>
                    <box size="0.55 0.5 0.1"/>
               </geometry> 
            </collision>

        </link>

        <joint name="base_joint" type="fixed">
            <parent link="world"/>
            <child link="base"/>
            <origin xyz="0.0 0.0 0.0" rpy="0.0 0.0 0.0"/>
        </joint>

        <link name="front_caster_of_the_right_wheel">
            <visual>
                <geometry>
                    <box size = "0.1 0.1 0.1"/>
                </geometry> 

                <material name = "Green">
                    <color rgba="0 1 0 1"/>
                </material>
            </visual>

            <inertial>
                <origin xyz="0.0 0.0 0.0" rpy="0.0 0.0 0.0"/>
                <mass value="0"/>
                <inertia ixx="0.00" ixy="0.0" ixz="0.0" iyy="0.00" iyz="0.0" izz="0.00"/>
            </inertial>

            <collision>
               <geometry>
                    <box size="0.1 0.1 0.1"/>
               </geometry> 
            </collision>

        </link>

        <joint name="front_caster_of_the_right_wheel_joint" type="continuous">
            <axis xyz="0.0 0.0 1"/>
            <parent link="base"/>
            <child link="front_caster_of_the_right_wheel"/>
            <origin xyz="0.275 -0.1 0.0" rpy="0.0 0.0 0.0"/>
        </joint> 

        <link name="front_right_wheel">
            <visual>
                <geometry>
                    <cylinder radius="0.0625" length="0.05"/>
                </geometry> 

                <material name = "Blue">
                    <color rgba="0 0 1 1"/>
                </material>
            </visual>

            <inertial>
                <origin xyz="0.0 0.0 0.0" rpy="0.0 0.0 0.0"/>
                <mass value="0"/>
                <inertia ixx="0.00" ixy="0.0" ixz="0.0" iyy="0.00" iyz="0.0" izz="0.00"/>
            </inertial>

            <collision>
               <geometry>
                    <cylinder radius="0.0625" length="0.05"/>
               </geometry> 
            </collision>

        </link>

        <joint name="front_right_wheel_joint" type="continuous">
            <axis xyz="0.0 0.0 1"/>
            <parent link="front_caster_of_the_right_wheel"/>
            <child link="front_right_wheel"/>
            <origin xyz="0.05 0.0 -0.05" rpy="-1.57 0.0 0.0"/>
        </joint> 

        <link name="front_caster_of_the_left_wheel">
            <visual>
                <geometry>
                    <box size = "0.1 0.1 0.1"/>
                </geometry> 

                <material name = "Green">
                    <color rgba="0 1 0 1"/>
                </material>
            </visual>

            <inertial>
                <origin xyz="0.0 0.0 0.0" rpy="0.0 0.0 0.0"/>
                <mass value="0"/>
                <inertia ixx="0.00" ixy="0.0" ixz="0.0" iyy="0.00" iyz="0.0" izz="0.00"/>
            </inertial>

            <collision>
               <geometry>
                    <box size="0.1 0.1 0.1"/>
               </geometry> 
            </collision>

        </link>

        <joint name="front_caster_of_the_left_wheel_joint" type="continuous">
            <axis xyz="0.0 0.0 1"/>
            <parent link="base"/>
            <child link="front_caster_of_the_left_wheel"/>
            <origin xyz="0.275 0.1 0.0" rpy="0.0 0.0 0.0"/>
        </joint> 

        <link name="front_left_wheel">
            <visual>
                <geometry>
                    <cylinder radius="0.0625" length="0.05"/>
                </geometry> 

                <material name = "Blue">
                    <color rgba="0 0 1 1"/>
                </material>
            </visual>

            <inertial>
                <origin xyz="0.0 0.0 0.0" rpy="0.0 0.0 0.0"/>
                <mass value="0"/>
                <inertia ixx="0.00" ixy="0.0" ixz="0.0" iyy="0.00" iyz="0.0" izz="0.00"/>
            </inertial>

            <collision>
               <geometry>
                    <cylinder radius="0.0625" length="0.05"/>
               </geometry> 
            </collision>

        </link>

        <joint name="front_left_wheel_joint" type="continuous">
            <axis xyz="0.0 0.0 1"/>
            <parent link="front_caster_of_the_left_wheel"/>
            <child link="front_left_wheel"/>
            <origin xyz="0.05 0.0 -0.05" rpy="-1.57 0.0 0.0"/>
        </joint> 

        <link name="right_wheel">
            <visual>
                <geometry>
                    <cylinder radius="0.0625" length="0.05"/>                
                </geometry> 

                <material name = "Blue">
                    <color rgba="0 0 1 1"/>
                </material>
            </visual>

            <inertial>
                <origin xyz="0.0 0.0 0.0" rpy="0.0 0.0 0.0"/>
                <mass value="0"/>
                <inertia ixx="0.00" ixy="0.0" ixz="0.0" iyy="0.00" iyz="0.0" izz="0.00"/>
            </inertial>

            <collision>
                <geometry>
                    <cylinder radius="0.0625" length="0.05"/>               
                </geometry> 
            </collision>

        </link>

        <joint name="right_wheel_joint" type="continuous">
            <axis xyz="0.0 0.0 1"/>
            <parent link="base"/>
            <child link="right_wheel"/>
            <origin xyz="0 -0.25 0" rpy="-1.57 0.0 0.0"/>
        </joint> 

        <link name="left_wheel">
            <visual>
                <geometry>
                    <cylinder radius="0.0625" length="0.05"/>
                </geometry> 

                <material name = "Blue">
                    <color rgba="0 0 1 1"/>
                </material>
            </visual>

            <inertial>
                <origin xyz="0.0 0.0 0.0" rpy="0.0 0.0 0.0"/>
                <mass value="0"/>
                <inertia ixx="0.00" ixy="0.0" ixz="0.0" iyy="0.00" iyz="0.0" izz="0.00"/>
            </inertial>

            <collision>
               <geometry>
                    <cylinder radius="0.0625" length="0.05"/>
               </geometry> 
            </collision>

        </link>

        <joint name="left_wheel_joint" type="continuous">
            <axis xyz="0.0 0.0 1"/>
            <parent link="base"/>
            <child link="left_wheel"/>
            <origin xyz="0 0.25 0" rpy="-1.57 0.0 0.0"/>
        </joint> 

    </robot>