<?xml version="1.0" ?>
    <robot name="explorer">
        <!--<link name="world"/> -->

        <link name="base">
            <visual>
                <geometry>
                    <box size="0.6 0.3 0.1"/>
                </geometry> 

                <material name = "red">
                    <color rgba="1 0 0 1"/>
                </material>
            </visual>

            <collision>
                <geometry>
                     <box size="0.6 0.3 0.1"/>
                </geometry> 
             </collision>

            <inertial>
                <mass value="1.0"/>
                <inertia ixx="0.00833" ixy="0" ixz="0" iyy="0.0308" iyz="0.0" izz="0.0375"/>
            </inertial> 

        </link>

        <!--<joint name="base_joint" type="fixed">
            <parent link="world"/>
            <child link="base"/>
        </joint>-->

        <link name="front_caster_of_wheel">
            <visual>
                <geometry>
                    <box size = "0.1 0.1 0.1"/>
                </geometry> 

                <material name = "Green">
                    <color rgba="0 1 0 1"/>
                </material>
            </visual>

            <collision>
                <geometry>
                     <box size="0.1 0.1 0.1"/>
                </geometry> 
             </collision>

            <inertial>
                <mass value="0.1"/>
                <inertia ixx="0.000167" ixy="0" ixz="0" iyy="0.000167" iyz="0.0" izz="0.000167"/>
            </inertial>


        </link>

        <joint name="front_caster_of_wheel_joint" type="continuous">
            <axis xyz="0.0 0.0 1"/>
            <parent link="base"/>
            <child link="front_caster_of_wheel"/>
            <origin xyz="0.3 0.0 0.0" rpy="0.0 0.0 0.0"/>
        </joint> 

        <link name="front_wheel">
            <visual>
                <geometry>
                    <cylinder radius="0.035" length="0.05"/>
                </geometry> 

                <material name = "Blue">
                    <color rgba="0 0 1 1"/>
                </material>
            </visual>

            <collision>
                <geometry>
                     <cylinder radius="0.035" length="0.05"/>
                </geometry> 
             </collision>

            <inertial>
                <mass value="0.1"/>
                <inertia ixx="5.1458e-5" ixy="0" ixz="0" iyy="5.1458e-5" iyz="0.0" izz="6.125e-5"/>
            </inertial>

        </link>

        <joint name="front_wheel_joint" type="continuous">
            <axis xyz="0.0 0.0 1"/>
            <parent link="front_caster_of_wheel"/>
            <child link="front_wheel"/>
            <origin xyz="0.05 0.0 -0.05" rpy="-1.5708 0.0 0.0"/>
        </joint> 

        <link name="right_wheel">
            <visual>
                <geometry>
                    <cylinder radius="0.035" length="0.05"/>
                </geometry> 

                <material name = "Blue">
                    <color rgba="0 0 1 1"/>
                </material>
            </visual>

            <collision>
                <geometry>
                    <cylinder radius="0.035" length="0.05"/>
                </geometry> 
             </collision>

            <inertial>
                <origin xyz="0.0 0.0 0.0" rpy="0.0 0.0 0.0"/>
                <mass value="0.1"/>
                <inertia ixx="5.1458e-5" ixy="0" ixz="0" iyy="5.1458e-5" iyz="0.0" izz="6.125e-5"/>
            </inertial>

        </link>

        <joint name="right_wheel_joint" type="continuous">
            <axis xyz="0.0 0.0 1"/>
            <parent link="base"/>
            <child link="right_wheel"/>
            <origin xyz="-0.2825 -0.125 -0.05" rpy="-1.5708 0.0 0.0"/>
        </joint> 

        <link name="left_wheel">
            <visual>
                <geometry>
                    <cylinder radius="0.035" length="0.05"/>
                </geometry> 

                <material name = "Blue">
                    <color rgba="0 0 1 1"/>
                </material>
            </visual>

            <collision>
                <geometry>
                     <cylinder radius="0.035" length="0.05"/>
                </geometry> 
             </collision>

            <inertial>
                <mass value="0.1"/>
                <inertia ixx="5.1458e-5" ixy="0" ixz="0" iyy="5.1458e-5" iyz="0.0" izz="6.125e-5"/>
            </inertial>

        </link>

        <joint name="left_wheel_joint" type="continuous">
            <axis xyz="0.0 0.0 1"/>
            <parent link="base"/>
            <child link="left_wheel"/>
            <origin xyz="-0.2825 0.125 -0.05" rpy="-1.5708 0.0 0.0"/>
        </joint> 

        <link name="laser_scanner">
            <visual>
                <geometry>
                    <box size="0.1 0.1 0.1"/>
                </geometry>
            </visual>
    
            <collision>
                <geometry>
                    <box size="0.1 0.1 0.1"/>
                </geometry>
            </collision>
    
            <inertial>
                <mass value="1e-5"/>
                <inertia ixx="1e-6" ixy="0" ixz="0.0" iyy="1e-6" iyz="0.0" izz="1e-6"/>
            </inertial>
        </link>
    
        <joint name="laser_scanner_joint" type="fixed">
            <axis xyz="0.0 1 0.0"/>
            <parent link="base"/>
            <child link="laser_scanner"/>
            <origin xyz="0.0 0.0 0.08" rpy="0.0 0.0 0.0"/>
        </joint>
    
        <gazebo reference="laser_scanner">
            <sensor type="ray" name="laser">
                <pose>0 0 0 0 0 0</pose>
                <visualize>true</visualize>
                <update_rate>40</update_rate>

                <ray>
                    <scan>
                        <horizontal>
                            <samples>720</samples>
                            <resolution>1</resolution>
                            <min_angle>-1.578</min_angle>
                            <max_angle>1.578</max_angle>
                        </horizontal>
                    </scan>
                    <range>
                        <min>0.1</min>
                        <max>10</max>
                        <resolution>0.1</resolution>
                    </range>
                </ray>

                <plugin name="Lidar" filename="libgazebo_ros_laser.so">
                    <topicName>scan</topicName>
                    <frameName>laser_scanner</frameName>
                </plugin>
                
            </sensor>
        </gazebo>

        <gazebo>
            <plugin name="explorer_bot_controller" filename="libgazebo_ros_diff_drive.so">
                <leftJoint>left_wheel_joint</leftJoint>
                <rightJoint>right_wheel_joint</rightJoint>
                <legacyMode>false</legacyMode>
                <robotBaseFrame>base</robotBaseFrame>
                <wheelSeparation>0.25</wheelSeparation>
                <wheelDiameter>0.07</wheelDiameter>
                <publishWheelJointState>true</publishWheelJointState>
                <odometryTopic>odom1</odometryTopic>
                <odometryFrame>odom</odometryFrame>
                <publishOdomTF>false</publishOdomTF>
            </plugin>
        </gazebo>

        <gazebo>
            <plugin name="joint_state_publisher" filename="libgazebo_ros_joint_state_publisher.so">
                <jointName>front_caster_of_wheel_joint, front_wheel_joint</jointName>
            </plugin>
        </gazebo>

        <gazebo reference="base">
            <material>Gazebo/Orange</material>
        </gazebo>
        <gazebo reference="front_caster_of_wheel">
            <material>Gazebo/Red</material>
        </gazebo>
        <gazebo reference="front_wheel">
            <material>Gazebo/Black</material>
        </gazebo>
        <gazebo reference="left_wheel">
            <material>Gazebo/Black</material>
        </gazebo>
        <gazebo reference="right_wheel">
            <material>Gazebo/Black</material>
        </gazebo>

        <gazebo>
            <plugin name="imu_plugin" filename="libgazebo_ros_imu.so">
              <alwaysOn>true</alwaysOn>
              <bodyName>base</bodyName>
              <topicName>/imu/data</topicName>
              <serviceName>imu_service</serviceName>
              <gaussianNoise>0.0</gaussianNoise>
              <updateRate>20.0</updateRate>
            </plugin>
        </gazebo>

    </robot>